Workbook
Name valuevx: 42.314159
Name vertex42_copyright: "© 2008-2019 Vertex42 LLC"
Name vertex42_id: "personal-budget-spreadsheet.xlsx"
Name vertex42_title: "Personal Budget Spreadsheet"

Sheet Input Sheet
A5: Income | B5: JAN | C5: FEB | D5: MAR | E5: APR | F5: MAY | G5: JUN | H5: JUL | I5: AUG | J5: SEP | K5: OCT | L5: NOV | M5: DEC | N5: Total | O5: Avg | Q5: Totals
A6: Salary | D6: =58.8 + 151.17 + 112.42 -> 322.39 | E6: =130.91 + 21.02 + 316.48 + 200.67 + 126.69 -> 795.77 | F6: =111.53 + 158.62 + 21.3 + 81.72 + 121.14 + 111.32 + 218.57 -> 824.2 | G6: =131.97 + 7.66 -> 139.63 | H6: =414.32 -> 414.32 | K6: =218.68 + 946.87 + 82.55 -> 1248.1 | L6: =749.54 -> 749.54 | M6: =717.25 + 66.3 + 745.94 -> 1529.49 | N6: =SUM(B6:M6) -> 6023.44 | O6: =N6/COLUMNS(B6:M6) -> 501.95333 | Q6: Total Income | R6: =N9 -> 21871.8
A7: Reimbursements | B7: =15.45 -> 15.45 | C7: =22 + 20 + 23 + 27 -> 92 | D7: =8.5 + 35 + 8.5 -> 52 | E7: =20 + 17 + 3 -> 40 | F7: =25.81 + 8 -> 33.81 | H7: =10+52+8.33+0.67+40.65+62.12 -> 173.77 | I7: =11.09 + 895.66 + 21.15 -> 927.9 | J7: =57 + 55 + 54 + 20 -> 186 | K7: =120 + 32 + 35 + 73 + 14 + 3 -> 277 | L7: =14 + 24.21 -> 38.21 | M7: =40 + 36.75 + 42.4 + 85.8 + 235 -> 439.95 | N7: =SUM(B7:M7) -> 2276.09 | O7: =N7/COLUMNS(B7:M7) -> 189.67417 | Q7: Total Expenses | R7: =SUM(N17,N26,N32,N43,N61,N66) -> 15290.04
A8: Other | B8: =30 + 30 + 6227.57 -> 6287.57 | C8: =30 + 35 -> 65 | D8: =20 + 20 -> 40 | E8: =40 -> 40 | F8: =50 + 100 + 460 + 107.5 + 48 + 1497.65 -> 2263.15 | G8: 655 | H8: =50+50 -> 100 | K8: =50 + 250 + 60 + 3436.55 -> 3796.55 | L8: =50 + 150 -> 200 | M8: =125 -> 125 | N8: =SUM(B8:M8) -> 13572.27 | O8: =N8/COLUMNS(B8:M8) -> 1131.0225 | Q8: Net | R8: =(R6-R7) -> 6581.76
A9: ="Total " & 'Input Sheet'!$A$5 -> Total Income | B9: =SUBTOTAL(109,'Input Sheet'!$B$6:$B$8) -> 6303.02 | C9: =SUBTOTAL(109,'Input Sheet'!$C$6:$C$8) -> 157 | D9: =SUBTOTAL(109,'Input Sheet'!$D$6:$D$8) -> 414.39 | E9: =SUBTOTAL(109,'Input Sheet'!$E$6:$E$8) -> 875.77 | F9: =SUBTOTAL(109,'Input Sheet'!$F$6:$F$8) -> 3121.16 | G9: =SUBTOTAL(109,'Input Sheet'!$G$6:$G$8) -> 794.63 | H9: =SUBTOTAL(109,'Input Sheet'!$H$6:$H$8) -> 688.09 | I9: =SUBTOTAL(109,'Input Sheet'!$I$6:$I$8) -> 927.9 | J9: =SUBTOTAL(109,'Input Sheet'!$J$6:$J$8) -> 186 | K9: =SUBTOTAL(109,'Input Sheet'!$K$6:$K$8) -> 5321.65 | L9: =SUBTOTAL(109,'Input Sheet'!$L$6:$L$8) -> 987.75 | M9: =SUBTOTAL(109,'Input Sheet'!$M$6:$M$8) -> 2094.44 | N9: =SUM(N6:N8) -> 21871.8 | O9: ='Input Sheet'!$N$9/COLUMNS('Input Sheet'!$B$9:$M$9) -> 1822.65
A11: Transportation | B11: JAN | C11: FEB | D11: MAR | E11: APR | F11: MAY | G11: JUN | H11: JUL | I11: AUG | J11: SEP | K11: OCT | L11: NOV | M11: DEC | N11: Total | O11: Avg
A12: NMBS | C12: =8.9 + 10.2 -> 19.1 | D12: =8.9 -> 8.9 | E12: =8.9 + 20.8 + 6.5 -> 36.2 | F12: =7.8 + 83.5 + 8.9 -> 100.2 | G12: =8.9 + 19.4 + 23.4 -> 51.7 | H12: =17.29+8.9 -> 26.19 | J12: =18.2 + 23.4 + 9.1 + 5.7 + 6.7 + 10.6 -> 73.7 | K12: =10.6 + 18.2 + 10.6 + 3 + 11 + 9.2 + 5.5 + 5.5 + 7.2 + 9.2 + 4.6 -> 94.6 | L12: =2.5 + 11 + 7.8 + 2.5 + 5.5 + 5.5 + 3 + 5.5 + 4.6 + 4.3 + 2.3 + 5.5 + 9.2 -> 69.2 | M12: =5.5 + 5.5 + 5.5 + 2.5 + 5.5 + 2.3 + 3.9 + 3.9 + 4.6 + 24 + 3.9 + 3.9 -> 71 | N12: =SUM(B12:M12) -> 550.79 | O12: =AVERAGE(B12:M12) -> 55.079
A13: Cambio | B13: 11.27 | C13: 4 | D13: =39.05 -> 39.05 | E13: 4 | F13: 4 | G13: 4 | H13: 4 | I13: 4 | J13: 4 | K13: =3 + 3 + 3 -> 9 | L13: 4 | M13: 4 | N13: =SUM(B13:M13) -> 95.32 | O13: =AVERAGE(B13:M13) -> 7.9433333
A14: Motorcycle | N14: =SUM(B14:M14) -> 0 | O14: =AVERAGE(B14:M14) -> #DIV/0!
A15: De Lijn | E15: =2.1 -> 2.1 | F15: =1.7 + 4.2 -> 5.9 | H15: =3.22+3.22+3.22+3.22+3.22+3.22+3.22 -> 22.54 | J15: =21 -> 21 | K15: =3 + 3 + 21 -> 27 | L15: =21 -> 21 | N15: =SUM(B15:M15) -> 99.54 | O15: =AVERAGE(B15:M15) -> 16.59
A16: Other | C16: =8.9 -> 8.9 | H16: =2.66 -> 2.66 | I16: =3.33 + 3.32 + 2.33 + 1.9 + 2 + 2.32 + 2.66 + 3.15 + 2.99 + 4.99 + 4.15 + 4.83 + 0.84 + 4.59 + 2.8 + 2.31 + 0.99 -> 49.5 | J16: =58 + 3.98 + 1.66 + 9.08 + 2.64 + 2 + 1.42 + 8.33 + 15.97 + 78 + 1.4 -> 182.48 | L16: =17.97 + 2.3 -> 20.27 | N16: =SUM(B16:M16) -> 263.81 | O16: =AVERAGE(B16:M16) -> 52.762
A17: ="Total "&'Input Sheet'!$A$11 -> Total Transportation | B17: =SUBTOTAL(109,'Input Sheet'!$B$12:$B$16) -> 11.27 | C17: =SUBTOTAL(109,'Input Sheet'!$C$12:$C$16) -> 32 | D17: =SUBTOTAL(109,'Input Sheet'!$D$12:$D$16) -> 47.95 | E17: =SUBTOTAL(109,'Input Sheet'!$E$12:$E$16) -> 42.3 | F17: =SUBTOTAL(109,'Input Sheet'!$F$12:$F$16) -> 110.1 | G17: =SUBTOTAL(109,'Input Sheet'!$G$12:$G$16) -> 55.7 | H17: =SUBTOTAL(109,'Input Sheet'!$H$12:$H$16) -> 55.39 | I17: =SUBTOTAL(109,'Input Sheet'!$I$12:$I$16) -> 53.5 | J17: =SUBTOTAL(109,'Input Sheet'!$J$12:$J$16) -> 281.18 | K17: =SUBTOTAL(109,'Input Sheet'!$K$12:$K$16) -> 130.6 | L17: =SUBTOTAL(109,'Input Sheet'!$L$12:$L$16) -> 114.47 | M17: =SUBTOTAL(109,'Input Sheet'!$M$12:$M$16) -> 75 | N17: =SUM(N12:N16) -> 1009.46 | O17: =AVERAGE(B12:M16) -> 30.589697
A19: Health | B19: JAN | C19: FEB | D19: MAR | E19: APR | F19: MAY | G19: JUN | H19: JUL | I19: AUG | J19: SEP | K19: OCT | L19: NOV | M19: DEC | N19: Total | O19: Avg
A20: Health Insurance | B20: =37.38 + 30 -> 67.38 | D20: 62 | E20: =30 + 37.38 -> 67.38 | H20: =30 + 37.38 -> 67.38 | K20: =30.9 + 37.56 -> 68.46 | N20: =SUM(B20:M20) -> 332.6 | O20: =AVERAGE(B20:M20) -> 66.52
A21: Medication | J21: =12.5 -> 12.5 | K21: =14.9 + 2.8 + 92.45 -> 110.15 | N21: =SUM(B21:M21) -> 122.65 | O21: =AVERAGE(B21:M21) -> 61.325
A22: Doctor | H22: =13.07 -> 13.07 | J22: =54 + 4 -> 58 | K22: =21.02 + 39 -> 60.02 | L22: =36.21 + 12.5 -> 48.71 | M22: =4 -> 4 | N22: =SUM(B22:M22) -> 183.8 | O22: =AVERAGE(B22:M22) -> 36.76
A23: Cosmetics | J23: =40.6 -> 40.6 | K23: =18.74 -> 18.74 | M23: =14.18 -> 14.18 | N23: =SUM(B23:M23) -> 73.52 | O23: =AVERAGE(B23:M23) -> 24.506667
A24: Sauna | C24: 46.9 | J24: =28 -> 28 | N24: =SUM(B24:M24) -> 74.9 | O24: =AVERAGE(B24:M24) -> 37.45
A25: Other | N25: =SUM(B25:M25) -> 0 | O25: =AVERAGE(B25:M25) -> #DIV/0!
A26: ="Total "&'Input Sheet'!$A$19 -> Total Health | B26: =SUBTOTAL(109,'Input Sheet'!$B$20:$B$25) -> 67.38 | C26: =SUBTOTAL(109,'Input Sheet'!$C$20:$C$25) -> 46.9 | D26: =SUBTOTAL(109,'Input Sheet'!$D$20:$D$25) -> 62 | E26: =SUBTOTAL(109,'Input Sheet'!$E$20:$E$25) -> 67.38 | F26: =SUBTOTAL(109,'Input Sheet'!$F$20:$F$25) -> 0 | G26: =SUBTOTAL(109,'Input Sheet'!$G$20:$G$25) -> 0 | H26: =SUBTOTAL(109,'Input Sheet'!$H$20:$H$25) -> 80.45 | I26: =SUBTOTAL(109,'Input Sheet'!$I$20:$I$25) -> 0 | J26: =SUBTOTAL(109,'Input Sheet'!$J$20:$J$25) -> 139.1 | K26: =SUBTOTAL(109,'Input Sheet'!$K$20:$K$25) -> 257.37 | L26: =SUBTOTAL(109,'Input Sheet'!$L$20:$L$25) -> 48.71 | M26: =SUBTOTAL(109,'Input Sheet'!$M$20:$M$25) -> 18.18 | N26: =SUM(N20:N25) -> 787.47 | O26: =AVERAGE(O20:O24) -> 45.312333
A28: Charity_Gifts | B28: JAN | C28: FEB | D28: MAR | E28: APR | F28: MAY | G28: JUN | H28: JUL | I28: AUG | J28: SEP | K28: OCT | L28: NOV | M28: DEC | N28: Total | O28: Avg
A29: Wikipedia | B29: 2 | C29: 2 | D29: 2 | E29: 2 | F29: 2 | G29: 2 | H29: 2 | I29: 2 | J29: 2 | K29: 2 | L29: 2 | M29: 2 | N29: =SUM(B29:M29) -> 24 | O29: =N29/COLUMNS(B29:M29) -> 2
A30: Gifts | C30: =9 -> 9 | E30: =10 + 31.5 -> 41.5 | F30: =15.99 + 20 -> 35.99 | G30: 76 | J30: =21.86 -> 21.86 | M30: =7.7 + 15.2 + 42.75 + 14 -> 79.65 | N30: =SUM(B30:M30) -> 264 | O30: =N30/COLUMNS(B30:M30) -> 22
A31: Other | N31: =SUM(B31:M31) -> 0 | O31: =N31/COLUMNS(B31:M31) -> 0
A32: ="Total " & 'Input Sheet'!$A$28 -> Total Charity_Gifts | B32: =SUBTOTAL(109,'Input Sheet'!$B$29:$B$31) -> 2 | C32: =SUBTOTAL(109,'Input Sheet'!$C$29:$C$31) -> 11 | D32: =SUBTOTAL(109,'Input Sheet'!$D$29:$D$31) -> 2 | E32: =SUBTOTAL(109,'Input Sheet'!$E$29:$E$31) -> 43.5 | F32: =SUBTOTAL(109,'Input Sheet'!$F$29:$F$31) -> 37.99 | G32: =SUBTOTAL(109,'Input Sheet'!$G$29:$G$31) -> 78 | H32: =SUBTOTAL(109,'Input Sheet'!$H$29:$H$31) -> 2 | I32: =SUBTOTAL(109,'Input Sheet'!$I$29:$I$31) -> 2 | J32: =SUBTOTAL(109,'Input Sheet'!$J$29:$J$31) -> 23.86 | K32: =SUBTOTAL(109,'Input Sheet'!$K$29:$K$31) -> 2 | L32: =SUBTOTAL(109,'Input Sheet'!$L$29:$L$30) -> 2 | M32: =SUBTOTAL(109,'Input Sheet'!$M$29:$M$31) -> 81.65 | N32: =SUBTOTAL(109,'Input Sheet'!$N$29:$N$31) -> 288 | O32: ='Input Sheet'!$N$32/COLUMNS('Input Sheet'!$B$32:$M$32) -> 24
A34: Daily_Living | B34: JAN | C34: FEB | D34: MAR | E34: APR | F34: MAY | G34: JUN | H34: JUL | I34: AUG | J34: SEP | K34: OCT | L34: NOV | M34: DEC | N34: Total | O34: Avg
A35: Groceries | B35: =41.21 + 38.14 + 12 + 0.75 + 42.75 + 43 + 4.9 + 47.3 -> 230.05 | C35: =6 + 3 + 4.8 + 25.95 + 25.18 + 2.15 -> 67.08 | D35: =32.24 + 1.85 + 48.1 + 3.97 -> 86.16 | E35: =1.85 + 5.07 + 9.99 + 15.12 + 29.37 + 10.15 + 8.1 + 9.16 -> 88.81 | F35: =11.68 + 22.58 + 37.93 + 21.94 -> 94.13 | G35: =1.52 + 5.83+3.96 -> 11.31 | H35: =41.97 + 9.38+32.69+7.91+11.39+29.9+17.22+14.07+7+21.6 -> 193.13 | J35: =2.82 + 30.48 -> 33.3 | K35: =12.49 + 28 + 65.07 + 9.71 + 3 + 44.72 + 14.2 + 3.88 + 37.47 + 3 + 8.27 -> 229.81 | L35: =20.17 + 4.95 + 21.36 + 8.51 + 86.12 + 28.85 -> 169.96 | M35: =7.64 + 5.95 + 6.5 + 49.18 + 9.35 + 14.24 + 7.48 + 4.95 + 13.77 + 21.63 -> 140.69 | N35: =SUM(B35:M35) -> 1344.43 | O35: =N35/COLUMNS(B35:M35) -> 112.03583
A36: Phone bill | B36: 15 | C36: 15 | D36: 15 | E36: 17.83 | F36: 15 | G36: 15 | H36: 15 | I36: 15 | J36: 45.83 | K36: 15 | L36: 15 | M36: 15 | N36: =SUM(B36:M36) -> 213.66 | O36: =N36/COLUMNS(B36:M36) -> 17.805
A37: Rent | B37: 195 | C37: 195 | D37: 195 | E37: =195 + 736.54 -> 931.54 | F37: 195 | G37: 195 | H37: 195 | N37: =SUM(B37:M37) -> 2101.54 | O37: =N37/COLUMNS(B37:M37) -> 175.12833
A38: Clothes | G38: =83.93 + 25 -> 108.93 | H38: =19.98 -> 19.98 | K38: =45.8 -> 45.8 | L38: =5 + 33.7 + 7 + 99.95 + 149.55 + 22.04 + 50 + 9.8 + 18 + 15.4 + 7.69 + 23.92 + 51.2 + 86.54 + 35.09 + 1.38 + 1.98 -> 618.24 | M38: =35.24 + 89.59 + 20.63 -> 145.46 | N38: =SUM(B38:M38) -> 938.41 | O38: =N38/COLUMNS(B38:M38) -> 78.200833
A39: Laundry | B39: =16 + 7.5 -> 23.5 | H39: =2.68+2.15+2.68+2.68 -> 10.19 | N39: =SUM(B39:M39) -> 33.69 | O39: =N39/COLUMNS(B39:M39) -> 2.8075
A40: Education/Lessons | C40: 12.99 | G40: =11 -> 11 | N40: =SUM(B40:M40) -> 23.99 | O40: =N40/COLUMNS(B40:M40) -> 1.9991667
A41: Barber | L41: =15 + 23 -> 38 | M41: =23 -> 23 | N41: =SUM(B41:M41) -> 61 | O41: =N41/COLUMNS(B41:M41) -> 5.0833333
A42: Other | D42: =19.99 + 10.99 -> 30.98 | E42: =24.99 -> 24.99 | F42: 50 | H42: =1.9 + 2.99+0.39+0.86+2.74+0.9+0.86+0.28+1.27+0.38+0.38+0.45+1.16+1.15+0.88+0.68+0.44+1.19+3.67+1+4+67.5 -> 95.07 | I42: 20.81 | J42: =25 + 9.5 + 20.59 + 50 -> 105.09 | K42: =1.9 + 1 + 1.1 + 29 + 1.1 + 20.82 + 1.42 + 40 -> 96.34 | M42: =62.5 -> 62.5 | N42: =SUM(B42:M42) -> 485.78 | O42: =N42/COLUMNS(B42:M42) -> 40.481667
A43: ="Total " & 'Input Sheet'!$A$34 -> Total Daily_Living | B43: =SUBTOTAL(109,'Input Sheet'!$B$35:$B$42) -> 463.55 | C43: =SUBTOTAL(109,'Input Sheet'!$C$35:$C$42) -> 290.07 | D43: =SUBTOTAL(109,'Input Sheet'!$D$35:$D$42) -> 327.14 | E43: =SUBTOTAL(109,'Input Sheet'!$E$35:$E$42) -> 1063.17 | F43: =SUBTOTAL(109,'Input Sheet'!$F$35:$F$42) -> 354.13 | G43: =SUBTOTAL(109,'Input Sheet'!$G$35:$G$42) -> 341.24 | H43: =SUBTOTAL(109,'Input Sheet'!$H$35:$H$42) -> 528.37 | I43: =SUBTOTAL(109,'Input Sheet'!$I$35:$I$42) -> 35.81 | J43: =SUBTOTAL(109,'Input Sheet'!$J$35:$J$42) -> 184.22 | K43: =SUBTOTAL(109,'Input Sheet'!$K$35:$K$42) -> 386.95 | L43: =SUBTOTAL(109,'Input Sheet'!$L$35:$L$42) -> 841.2 | M43: =SUBTOTAL(109,'Input Sheet'!$M$35:$M$42) -> 386.65 | N43: =SUM(N35:N42) -> 5202.5 | O43: =AVERAGE(O35:O42) -> 54.192708
A45: Entertainment | B45: JAN | C45: FEB | D45: MAR | E45: APR | F45: MAY | G45: JUN | H45: JUL | I45: AUG | J45: SEP | K45: OCT | L45: NOV | M45: DEC | N45: Total | O45: Avg
A46: Dining/Eating Out | B46: =2 + 14.8 + 6.5 + 6.5 + 6.5 -> 36.3 | C46: =6 + 21.8 + 14.8 + 14.8 + 27.3 + 16.8 + 4 + 12 -> 117.5 | D46: =14.8 + 17.8 + 16.5 + 14 + 7.5 + 13.3 + 8 + 7.5 + 36 -> 135.4 | E46: =4.9 + 10 + 4.9 + 4.9 + 4.9 + 7 + 6.3 + 6.5 + 8.6 + 4.3 + 7 + 14.8 + 4.2 + 3.5 + 4.9 + 6.5 + 17 + 6.8 + 15.5 + 14 -> 156.5 | F46: =6.5 + 31.81 + 1 + 11 + 4.8 + 17.5 + 11.4 + 2 + 6.5 + 8.5 + 26 -> 127.01 | G46: =11 + 9 + 7 + 15.5 -> 42.5 | H46: =2.45 + 25.34+17.43+4.69+7.64+17.7+14.07+4.69+4.69+2.55+5.1+6+15.48 + 62 -> 189.83 | J46: =9.2 + 4.4 + 60 + 12 + 30 + 7.7 + 9.85 + 8.6 + 2.64 + 8.6 + 2.95 + 4.5 + 1.8 + 19.35 + 8 + 5.6 + 15 + 10.5 + 18.9 -> 239.59 | K46: =17.1 + 16.75 + 14 + 20 + 20.4 + 3.7 + 6 + 64 + 9.95 + 3.4 + 10 + 4.3 + 28 + 11 + 10 + 2.85 + 17.9 -> 259.35 | L46: =14.15 + 3 + 37 + 12 + 68.5 + 7 + 22 + 16.2 + 7.5 + 3 + 8 + 14.9 + 1.5 + 11.5 + 24.7 -> 250.95 | M46: =7 + 7.16 + 4 + 14.25 + 9.5 + 23 + 26.8 + 1.45 + 9 + 30 + 15 + 12.7 + 32 + 55.5 + 14 + 4.1 -> 265.46 | N46: =SUM(B46:M46) -> 1820.39 | O46: =N46/COLUMNS(B46:M46) -> 151.69917
A47: Drinks | C47: =17.85 + 3 + 13.5 -> 34.35 | E47: =3 + 12.8 -> 15.8 | H47: =4.69+7.37+4.4+7.4+3 -> 26.86 | J47: =6.13 + 2.9 + 1.99 -> 11.02 | K47: =11.25 + 6.2 + 6.5 + 3 + 5 + 13.5 -> 45.45 | L47: =14.5 + 28.8 + 2.9 + 13.3 + 9.6 + 9.6 + 9.6 -> 88.3 | M47: =11.4 + 41 + 6.79 + 35.3 + 13.99 + 30 + 6 + 33 + 8.1 + 11 + 2.9 + 4.5 + 3.2 + 5.8 + 2 -> 214.98 | N47: =SUM(B47:M47) -> 436.76 | O47: =N47/COLUMNS(B47:M47) -> 36.396667
A48: Coffee | C48: =1.97 + 1.97 + 1.6 + 7.7 -> 13.24 | D48: =1.97 + 1.97 + 1.97 + 1.97 + 3.6 -> 11.48 | E48: =1.97 + 1.97 -> 3.94 | F48: =1.97 + 6 -> 7.97 | G48: =1.59 + 3.2 -> 4.79 | H48: =2.01+2.01+2.01+2.01 -> 8.04 | J48: =3.46 -> 3.46 | L48: =21.5 -> 21.5 | M48: =3.4 + 4.8 + 7.9 -> 16.1 | N48: =SUM(B48:M48) -> 90.52 | O48: =N48/COLUMNS(B48:M48) -> 7.5433333
A49: HEMA | N49: =SUM(B49:M49) -> 0 | O49: =N49/COLUMNS(B49:M49) -> 0
...
